2025-09-05T10:02:22|WARNING|LoggedQuantity|dynamic_range read_from_hardware called when not connected to hardware
2025-09-05T10:02:22|CRITICAL|root|Unhandled exception: Traceback (most recent call last):
  File "C:\Users\lightsheet\AppData\Local\Programs\Python\Python312\Lib\site-packages\ScopeFoundry\hardware.py", line 100, in enable_connection
    raise err
  File "C:\Users\lightsheet\AppData\Local\Programs\Python\Python312\Lib\site-packages\ScopeFoundry\hardware.py", line 90, in enable_connection
    self.connect()
  File "C:\LabProgram\Shutter_ScopeFoundry\shutter_hw.py", line 39, in connect
    self.shutter = ShutterDevice(port = self.port.val, debug=self.debug_mode.val)
                   ^^^^^^^^^^^^^^^^^^^^^^^^^^^^^^^^^^^^^^^^^^^^^^^^^^^^^^^^^^^^^^
  File "C:\LabProgram\Shutter_ScopeFoundry\shutter_device.py", line 37, in __init__
    self.ser = ser = serial.Serial(port=self.port , baudrate=19200 ,bytesize=8  #define another attribute named ser,
                    ^^^^^^^^^^^^^^^^^^^^^^^^^^^^^^^^^^^^^^^^^^^^^^^^^^^^^^^^^^^^^^^^^^^^^^^^^^^^^^^^^^^^^^^^^^^^^^^
  File "C:\Users\lightsheet\AppData\Local\Programs\Python\Python312\Lib\site-packages\serial\serialwin32.py", line 33, in __init__
    super(Serial, self).__init__(*args, **kwargs)
  File "C:\Users\lightsheet\AppData\Local\Programs\Python\Python312\Lib\site-packages\serial\serialutil.py", line 244, in __init__
    self.open()
  File "C:\Users\lightsheet\AppData\Local\Programs\Python\Python312\Lib\site-packages\serial\serialwin32.py", line 64, in open
    raise SerialException("could not open port {!r}: {!r}".format(self.portstr, ctypes.WinError()))
serial.serialutil.SerialException: could not open port 'COM5': FileNotFoundError(2, 'The system cannot find the file specified.', None, 2)

2025-09-05T10:02:30|INFO|SPIM_app|proposed values Settings.ini
2025-09-05T10:02:30|INFO|SPIM_app|settings loaded from C:\LabProgram\SPIM_System\Settings\Settings.ini
2025-09-05T10:04:08|INFO|SPIM_app|proposed values 250905_100408_settings.ini
2025-09-05T10:04:08|INFO|SPIM_app|settings saved to D:\DATA\temp\250905_100408_settings.ini
2025-09-05T10:04:31|INFO|SPIM_app|proposed values Settings.ini
2025-09-05T10:04:31|INFO|SPIM_app|settings saved to C:/LabProgram/SPIM_System/Settings/Settings.ini
2025-09-05T10:05:08|CRITICAL|root|Unhandled exception: Traceback (most recent call last):
  File "C:\Users\lightsheet\AppData\Local\Programs\Python\Python312\Lib\site-packages\ScopeFoundry\measurement.py", line 29, in run
    self.measurement._thread_run()
  File "C:\Users\lightsheet\AppData\Local\Programs\Python\Python312\Lib\site-packages\ScopeFoundry\measurement.py", line 242, in _thread_run
    self.run()
  File "C:\LabProgram\SPIM_System\SPIM_measure.py", line 358, in run
    self.measure()
  File "C:\LabProgram\SPIM_System\SPIM_measure.py", line 190, in measure
    maxIP_img = np.zeros(w,h)
                ^^^^^^^^^^^^^
TypeError: Cannot interpret '2160' as a data type

2025-09-05T10:06:47|INFO|SPIM_app|on_close
2025-09-05T10:06:47|INFO|SPIM_app|disconnecting NeoAndorHW
2025-09-05T10:06:47|INFO|SPIM_app|disconnecting Shutter
2025-09-05T10:06:47|INFO|SPIM_app|disconnecting PI_CG_HW
